// Test output.
void testPrint(const char * const str, ...);

exception ExampleError(int value);

// Entry point.
int testEntryPoint(int argc, char ** argv) {
	try {
		testPrint(C"2: Executing 1.");
		try {
			testPrint(C"1: Executing 0.");
			try {
				testPrint(C"0: Throwing.");
				throw ExampleError(333);
				testPrint(C"0: THROW ERROR!");
			} catch (ExampleError error) {
				testPrint(C"0: Caught error with value %d.", error.value);
			}
			testPrint(C"1: Successfully finished 0.");
			
			testPrint(C"1: Throwing.");
			throw ExampleError(444);
			testPrint(C"1: THROW ERROR!");
		} catch (ExampleError error) {
			testPrint(C"1: Caught error with value %d.", error.value);
		}
		testPrint(C"2: Successfully finished 1.");
	} catch (ExampleError error) {
		testPrint(C"2: Caught error with value %d.", error.value);
	}
	return 0;
}

