// Test output.
void testPrint(const char * const str, ...);

exception ExampleError(int value);

// Entry point.
int testEntryPoint(int argc, char ** argv) {
	try {
		testPrint("2: Executing 1.");
		try {
			testPrint("1: Executing 0.");
			try {
				testPrint("0: Throwing.");
				throw ExampleError(333333);
				testPrint("0: THROW ERROR!");
			} catch (ExampleError error) {
				testPrint("0: Caught error with value %d.", error.value);
			}
			testPrint("1: Successfully finished 0.");
			
			testPrint("1: Throwing.");
			throw ExampleError(444444);
			testPrint("1: THROW ERROR!");
		} catch (ExampleError error) {
			testPrint("1: Caught error with value %d.", error.value);
		}
		testPrint("2: Successfully finished 1.");
	} catch (ExampleError error) {
		testPrint("2: Caught error with value %d.", error.value);
	}
	return 0;
}

